ERROR:root:Erro na sua_funcao: cannot access local variable 'gui_resp' where it is not associated with a value 
Traceback (most recent call last):
  File "/home/wendellast/Documents/GitHub/Gui/gui.py", line 53, in action_response
    [(f"{self.input.value}", f"{gui_resp}")],
                                ^^^^^^^^
UnboundLocalError: cannot access local variable 'gui_resp' where it is not associated with a value
ERROR:root:Erro na sua_funcao: cannot access local variable 'gui_resp' where it is not associated with a value 
Traceback (most recent call last):
  File "/home/wendellast/Documents/GitHub/Gui/gui.py", line 68, in action_response
    msg_gui = f"""[purple b] Gui: [/] [purple] {gui_resp} [/]"""
                                                ^^^^^^^^
UnboundLocalError: cannot access local variable 'gui_resp' where it is not associated with a value
ERROR:root:No `type` found in response: {'message': 'Internal Error'}
ERROR:root:No `type` found in response: {'message': 'Internal Error'}
ERROR:root:No `type` found in response: {'message': 'Internal Error'}
ERROR:root:No `type` found in response: {'message': 'Internal Error'}
ERROR:root:Erro na sua_funcao: Response Error 
Traceback (most recent call last):
  File "/home/wendellast/Documents/GitHub/Gui/gui.py", line 39, in action_response
    gui_resp = response_gui(self.input.value) +1
               ~~~~~~~~~~~~~~~~~~~~~~~~~~~~~~~^~
TypeError: can only concatenate str (not "int") to str
ERROR:root:Erro na sua_funcao: cannot access local variable 'gui_resp' where it is not associated with a value 
Traceback (most recent call last):
  File "/home/wendellast/Documents/GitHub/Gui/gui.py", line 54, in action_response
    [(f"{self.input.value}", f"{gui_resp}")],
                                ^^^^^^^^
UnboundLocalError: cannot access local variable 'gui_resp' where it is not associated with a value
ERROR:root:Erro na sua_funcao: cannot access local variable 'gui_resp' where it is not associated with a value 
Traceback (most recent call last):
  File "/home/wendellast/Documents/GitHub/Gui/gui.py", line 70, in action_response
    msg_gui = f"""[purple b] Gui: [/] [purple] {gui_resp} [/]"""
                                                ^^^^^^^^
UnboundLocalError: cannot access local variable 'gui_resp' where it is not associated with a value
ERROR:root:Erro na sua_funcao: Response Error 
Traceback (most recent call last):
  File "/home/wendellast/Documents/GitHub/Gui/gui.py", line 39, in action_response
    gui_resp = response_gui(self.input.value) +1
               ~~~~~~~~~~~~~~~~~~~~~~~~~~~~~~~^~
TypeError: can only concatenate str (not "int") to str
ERROR:root:Erro na sua_funcao: Response Error 
Traceback (most recent call last):
  File "/home/wendellast/Documents/GitHub/Gui/gui.py", line 39, in action_response
    gui_resp = response_gui(self.input.value) + 1
               ~~~~~~~~~~~~~~~~~~~~~~~~~~~~~~~^~~
TypeError: can only concatenate str (not "int") to str
ERROR:root:Erro na sua_funcao: cannot access local variable 'gui_resp' where it is not associated with a value 
Traceback (most recent call last):
  File "/home/wendellast/Documents/GitHub/Gui/gui.py", line 54, in action_response
    [(f"{self.input.value}", f"{gui_resp}")],
                                ^^^^^^^^
UnboundLocalError: cannot access local variable 'gui_resp' where it is not associated with a value
ERROR:root:Erro na sua_funcao: cannot access local variable 'gui_resp' where it is not associated with a value 
Traceback (most recent call last):
  File "/home/wendellast/Documents/GitHub/Gui/gui.py", line 70, in action_response
    msg_gui = f"""[purple b] Gui: [/] [purple] {gui_resp} [/]"""
                                                ^^^^^^^^
UnboundLocalError: cannot access local variable 'gui_resp' where it is not associated with a value
ERROR:root:Erro na sua_funcao: Response Error 
Traceback (most recent call last):
  File "/home/wendellast/Documents/GitHub/Gui/gui.py", line 39, in action_response
    gui_resp = response_gui(self.input.value) + 1
               ~~~~~~~~~~~~~~~~~~~~~~~~~~~~~~~^~~
TypeError: can only concatenate str (not "int") to str
ERROR:root:Erro na sua_funcao: cannot access local variable 'gui_resp' where it is not associated with a value 
Traceback (most recent call last):
  File "/home/wendellast/Documents/GitHub/Gui/gui.py", line 54, in action_response
    [(f"{self.input.value}", f"{gui_resp}")],
                                ^^^^^^^^
UnboundLocalError: cannot access local variable 'gui_resp' where it is not associated with a value
ERROR:root:Erro na sua_funcao: cannot access local variable 'gui_resp' where it is not associated with a value 
Traceback (most recent call last):
  File "/home/wendellast/Documents/GitHub/Gui/gui.py", line 70, in action_response
    msg_gui = f"""[purple b] Gui: [/] [purple] {gui_resp} [/]"""
                                                ^^^^^^^^
UnboundLocalError: cannot access local variable 'gui_resp' where it is not associated with a value
ERROR:root:Erro na sua_funcao: Response Error 
Traceback (most recent call last):
  File "/home/wendellast/Documents/GitHub/Gui/gui.py", line 39, in action_response
    gui_resp = response_gui(self.input.value) + 1
               ~~~~~~~~~~~~~~~~~~~~~~~~~~~~~~~^~~
TypeError: can only concatenate str (not "int") to str
ERROR:root:Erro na sua_funcao: cannot access local variable 'gui_resp' where it is not associated with a value 
Traceback (most recent call last):
  File "/home/wendellast/Documents/GitHub/Gui/gui.py", line 54, in action_response
    [(f"{self.input.value}", f"{gui_resp}")],
                                ^^^^^^^^
UnboundLocalError: cannot access local variable 'gui_resp' where it is not associated with a value
ERROR:root:Erro na sua_funcao: cannot access local variable 'gui_resp' where it is not associated with a value 
Traceback (most recent call last):
  File "/home/wendellast/Documents/GitHub/Gui/gui.py", line 70, in action_response
    msg_gui = f"""[purple b] Gui: [/] [purple] {gui_resp} [/]"""
                                                ^^^^^^^^
UnboundLocalError: cannot access local variable 'gui_resp' where it is not associated with a value
ERROR:root:Erro na sua_funcao: Response Error 
Traceback (most recent call last):
  File "/home/wendellast/Documents/GitHub/Gui/gui.py", line 39, in action_response
    gui_resp = response_gui(self.input.value) + 1
               ~~~~~~~~~~~~~~~~~~~~~~~~~~~~~~~^~~
TypeError: can only concatenate str (not "int") to str
ERROR:root:Erro na sua_funcao: cannot access local variable 'gui_resp' where it is not associated with a value 
Traceback (most recent call last):
  File "/home/wendellast/Documents/GitHub/Gui/gui.py", line 54, in action_response
    [(f"{self.input.value}", f"{gui_resp}")],
                                ^^^^^^^^
UnboundLocalError: cannot access local variable 'gui_resp' where it is not associated with a value
ERROR:root:Erro na sua_funcao: cannot access local variable 'gui_resp' where it is not associated with a value 
Traceback (most recent call last):
  File "/home/wendellast/Documents/GitHub/Gui/gui.py", line 70, in action_response
    msg_gui = f"""[purple b] Gui: [/] [purple] {gui_resp} [/]"""
                                                ^^^^^^^^
UnboundLocalError: cannot access local variable 'gui_resp' where it is not associated with a value
ERROR:root:Erro na sua_funcao: Response Error 
Traceback (most recent call last):
  File "/home/wendellast/Documents/GitHub/Gui/gui.py", line 39, in action_response
    gui_resp = response_gui(self.input.value) + 1
               ~~~~~~~~~~~~~~~~~~~~~~~~~~~~~~~^~~
TypeError: can only concatenate str (not "int") to str
ERROR:root:Erro na sua_funcao: Response Error 
Traceback (most recent call last):
  File "/home/wendellast/Documents/GitHub/Gui/api/apple.py", line 56, in create_chatbot
    cookies = sign.login()
              ^^^^^^^^^^^^
  File "/home/wendellast/Documents/GitHub/Gui/venv/lib/python3.11/site-packages/hugchat/login.py", line 33, in login
    self._sign_in_with_email()
  File "/home/wendellast/Documents/GitHub/Gui/venv/lib/python3.11/site-packages/hugchat/login.py", line 134, in _sign_in_with_email
    raise Exception("wrong username or password")
Exception: wrong username or password

During handling of the above exception, another exception occurred:

Traceback (most recent call last):
  File "/home/wendellast/Documents/GitHub/Gui/gui.py", line 39, in action_response
    gui_resp = response_gui(self.input.value) + 1
               ^^^^^^^^^^^^^^^^^^^^^^^^^^^^^^
  File "/home/wendellast/Documents/GitHub/Gui/api/orange.py", line 58, in response_gui
    return llm(resp)
           ^^^^^^^^^
  File "/home/wendellast/Documents/GitHub/Gui/venv/lib/python3.11/site-packages/langchain_core/_api/deprecation.py", line 145, in warning_emitting_wrapper
    return wrapped(*args, **kwargs)
           ^^^^^^^^^^^^^^^^^^^^^^^^
  File "/home/wendellast/Documents/GitHub/Gui/venv/lib/python3.11/site-packages/langchain_core/language_models/llms.py", line 991, in __call__
    self.generate(
  File "/home/wendellast/Documents/GitHub/Gui/venv/lib/python3.11/site-packages/langchain_core/language_models/llms.py", line 741, in generate
    output = self._generate_helper(
             ^^^^^^^^^^^^^^^^^^^^^^
  File "/home/wendellast/Documents/GitHub/Gui/venv/lib/python3.11/site-packages/langchain_core/language_models/llms.py", line 605, in _generate_helper
    raise e
  File "/home/wendellast/Documents/GitHub/Gui/venv/lib/python3.11/site-packages/langchain_core/language_models/llms.py", line 592, in _generate_helper
    self._generate(
  File "/home/wendellast/Documents/GitHub/Gui/venv/lib/python3.11/site-packages/langchain_core/language_models/llms.py", line 1177, in _generate
    self._call(prompt, stop=stop, run_manager=run_manager, **kwargs)
  File "/home/wendellast/Documents/GitHub/Gui/api/apple.py", line 101, in _call
    self.create_chatbot() if not self.chatbot else None
    ^^^^^^^^^^^^^^^^^^^^^
  File "/home/wendellast/Documents/GitHub/Gui/api/apple.py", line 75, in create_chatbot
    raise ValueError(
ValueError: LogIn failed. Please check your credentials or cookie_path. wrong username or password
ERROR:root:Erro na sua_funcao: Response Error 
Traceback (most recent call last):
  File "/home/wendellast/Documents/GitHub/Gui/api/apple.py", line 56, in create_chatbot
    cookies = sign.login()
              ^^^^^^^^^^^^
  File "/home/wendellast/Documents/GitHub/Gui/venv/lib/python3.11/site-packages/hugchat/login.py", line 33, in login
    self._sign_in_with_email()
  File "/home/wendellast/Documents/GitHub/Gui/venv/lib/python3.11/site-packages/hugchat/login.py", line 134, in _sign_in_with_email
    raise Exception("wrong username or password")
Exception: wrong username or password

During handling of the above exception, another exception occurred:

Traceback (most recent call last):
  File "/home/wendellast/Documents/GitHub/Gui/gui.py", line 39, in action_response
    gui_resp = response_gui(self.input.value) + 1
               ^^^^^^^^^^^^^^^^^^^^^^^^^^^^^^
  File "/home/wendellast/Documents/GitHub/Gui/api/orange.py", line 58, in response_gui
    return llm(resp)
           ^^^^^^^^^
  File "/home/wendellast/Documents/GitHub/Gui/venv/lib/python3.11/site-packages/langchain_core/_api/deprecation.py", line 145, in warning_emitting_wrapper
    return wrapped(*args, **kwargs)
           ^^^^^^^^^^^^^^^^^^^^^^^^
  File "/home/wendellast/Documents/GitHub/Gui/venv/lib/python3.11/site-packages/langchain_core/language_models/llms.py", line 991, in __call__
    self.generate(
  File "/home/wendellast/Documents/GitHub/Gui/venv/lib/python3.11/site-packages/langchain_core/language_models/llms.py", line 741, in generate
    output = self._generate_helper(
             ^^^^^^^^^^^^^^^^^^^^^^
  File "/home/wendellast/Documents/GitHub/Gui/venv/lib/python3.11/site-packages/langchain_core/language_models/llms.py", line 605, in _generate_helper
    raise e
  File "/home/wendellast/Documents/GitHub/Gui/venv/lib/python3.11/site-packages/langchain_core/language_models/llms.py", line 592, in _generate_helper
    self._generate(
  File "/home/wendellast/Documents/GitHub/Gui/venv/lib/python3.11/site-packages/langchain_core/language_models/llms.py", line 1177, in _generate
    self._call(prompt, stop=stop, run_manager=run_manager, **kwargs)
  File "/home/wendellast/Documents/GitHub/Gui/api/apple.py", line 101, in _call
    self.create_chatbot() if not self.chatbot else None
    ^^^^^^^^^^^^^^^^^^^^^
  File "/home/wendellast/Documents/GitHub/Gui/api/apple.py", line 75, in create_chatbot
    raise ValueError(
ValueError: LogIn failed. Please check your credentials or cookie_path. wrong username or password
ERROR:root:Erro na sua_funcao: cannot access local variable 'gui_resp' where it is not associated with a value 
Traceback (most recent call last):
  File "/home/wendellast/Documents/GitHub/Gui/gui.py", line 54, in action_response
    [(f"{self.input.value}", f"{gui_resp}")],
                                ^^^^^^^^
UnboundLocalError: cannot access local variable 'gui_resp' where it is not associated with a value
ERROR:root:Erro na sua_funcao: cannot access local variable 'gui_resp' where it is not associated with a value 
Traceback (most recent call last):
  File "/home/wendellast/Documents/GitHub/Gui/gui.py", line 70, in action_response
    msg_gui = f"""[purple b] Gui: [/] [purple] {gui_resp} [/]"""
                                                ^^^^^^^^
UnboundLocalError: cannot access local variable 'gui_resp' where it is not associated with a value
ERROR:root:Erro na sua_funcao: Response Error 
Traceback (most recent call last):
  File "/home/wendellast/Documents/GitHub/Gui/api/apple.py", line 56, in create_chatbot
    cookies = sign.login()
              ^^^^^^^^^^^^
  File "/home/wendellast/Documents/GitHub/Gui/venv/lib/python3.11/site-packages/hugchat/login.py", line 33, in login
    self._sign_in_with_email()
  File "/home/wendellast/Documents/GitHub/Gui/venv/lib/python3.11/site-packages/hugchat/login.py", line 134, in _sign_in_with_email
    raise Exception("wrong username or password")
Exception: wrong username or password

During handling of the above exception, another exception occurred:

Traceback (most recent call last):
  File "/home/wendellast/Documents/GitHub/Gui/gui.py", line 39, in action_response
    gui_resp = response_gui(self.input.value) + 1
               ^^^^^^^^^^^^^^^^^^^^^^^^^^^^^^
  File "/home/wendellast/Documents/GitHub/Gui/api/orange.py", line 58, in response_gui
    return llm(resp)
           ^^^^^^^^^
  File "/home/wendellast/Documents/GitHub/Gui/venv/lib/python3.11/site-packages/langchain_core/_api/deprecation.py", line 145, in warning_emitting_wrapper
    return wrapped(*args, **kwargs)
           ^^^^^^^^^^^^^^^^^^^^^^^^
  File "/home/wendellast/Documents/GitHub/Gui/venv/lib/python3.11/site-packages/langchain_core/language_models/llms.py", line 991, in __call__
    self.generate(
  File "/home/wendellast/Documents/GitHub/Gui/venv/lib/python3.11/site-packages/langchain_core/language_models/llms.py", line 741, in generate
    output = self._generate_helper(
             ^^^^^^^^^^^^^^^^^^^^^^
  File "/home/wendellast/Documents/GitHub/Gui/venv/lib/python3.11/site-packages/langchain_core/language_models/llms.py", line 605, in _generate_helper
    raise e
  File "/home/wendellast/Documents/GitHub/Gui/venv/lib/python3.11/site-packages/langchain_core/language_models/llms.py", line 592, in _generate_helper
    self._generate(
  File "/home/wendellast/Documents/GitHub/Gui/venv/lib/python3.11/site-packages/langchain_core/language_models/llms.py", line 1177, in _generate
    self._call(prompt, stop=stop, run_manager=run_manager, **kwargs)
  File "/home/wendellast/Documents/GitHub/Gui/api/apple.py", line 101, in _call
    self.create_chatbot() if not self.chatbot else None
    ^^^^^^^^^^^^^^^^^^^^^
  File "/home/wendellast/Documents/GitHub/Gui/api/apple.py", line 75, in create_chatbot
    raise ValueError(
ValueError: LogIn failed. Please check your credentials or cookie_path. wrong username or password
ERROR:root:Erro na sua_funcao: Response Error 
Traceback (most recent call last):
  File "/home/wendellast/Documents/GitHub/Gui/api/apple.py", line 56, in create_chatbot
    cookies = sign.login()
              ^^^^^^^^^^^^
  File "/home/wendellast/Documents/GitHub/Gui/venv/lib/python3.11/site-packages/hugchat/login.py", line 33, in login
    self._sign_in_with_email()
  File "/home/wendellast/Documents/GitHub/Gui/venv/lib/python3.11/site-packages/hugchat/login.py", line 134, in _sign_in_with_email
    raise Exception("wrong username or password")
Exception: wrong username or password

During handling of the above exception, another exception occurred:

Traceback (most recent call last):
  File "/home/wendellast/Documents/GitHub/Gui/gui.py", line 39, in action_response
    gui_resp = response_gui(self.input.value) + 1
               ^^^^^^^^^^^^^^^^^^^^^^^^^^^^^^
  File "/home/wendellast/Documents/GitHub/Gui/api/orange.py", line 58, in response_gui
    return llm(resp)
           ^^^^^^^^^
  File "/home/wendellast/Documents/GitHub/Gui/venv/lib/python3.11/site-packages/langchain_core/_api/deprecation.py", line 145, in warning_emitting_wrapper
    return wrapped(*args, **kwargs)
           ^^^^^^^^^^^^^^^^^^^^^^^^
  File "/home/wendellast/Documents/GitHub/Gui/venv/lib/python3.11/site-packages/langchain_core/language_models/llms.py", line 991, in __call__
    self.generate(
  File "/home/wendellast/Documents/GitHub/Gui/venv/lib/python3.11/site-packages/langchain_core/language_models/llms.py", line 741, in generate
    output = self._generate_helper(
             ^^^^^^^^^^^^^^^^^^^^^^
  File "/home/wendellast/Documents/GitHub/Gui/venv/lib/python3.11/site-packages/langchain_core/language_models/llms.py", line 605, in _generate_helper
    raise e
  File "/home/wendellast/Documents/GitHub/Gui/venv/lib/python3.11/site-packages/langchain_core/language_models/llms.py", line 592, in _generate_helper
    self._generate(
  File "/home/wendellast/Documents/GitHub/Gui/venv/lib/python3.11/site-packages/langchain_core/language_models/llms.py", line 1177, in _generate
    self._call(prompt, stop=stop, run_manager=run_manager, **kwargs)
  File "/home/wendellast/Documents/GitHub/Gui/api/apple.py", line 101, in _call
    self.create_chatbot() if not self.chatbot else None
    ^^^^^^^^^^^^^^^^^^^^^
  File "/home/wendellast/Documents/GitHub/Gui/api/apple.py", line 75, in create_chatbot
    raise ValueError(
ValueError: LogIn failed. Please check your credentials or cookie_path. wrong username or password
ERROR:root:Erro na sua_funcao: cannot access local variable 'gui_resp' where it is not associated with a value 
Traceback (most recent call last):
  File "/home/wendellast/Documents/GitHub/Gui/gui.py", line 54, in action_response
    [(f"{self.input.value}", f"{gui_resp}")],
                                ^^^^^^^^
UnboundLocalError: cannot access local variable 'gui_resp' where it is not associated with a value
ERROR:root:Erro na sua_funcao: cannot access local variable 'gui_resp' where it is not associated with a value 
Traceback (most recent call last):
  File "/home/wendellast/Documents/GitHub/Gui/gui.py", line 70, in action_response
    msg_gui = f"""[purple b] Gui: [/] [purple] {gui_resp} [/]"""
                                                ^^^^^^^^
UnboundLocalError: cannot access local variable 'gui_resp' where it is not associated with a value
ERROR:root:Erro na sua_funcao: Response Error 
Traceback (most recent call last):
  File "/home/wendellast/Documents/GitHub/Gui/api/apple.py", line 56, in create_chatbot
    cookies = sign.login()
              ^^^^^^^^^^^^
  File "/home/wendellast/Documents/GitHub/Gui/venv/lib/python3.11/site-packages/hugchat/login.py", line 33, in login
    self._sign_in_with_email()
  File "/home/wendellast/Documents/GitHub/Gui/venv/lib/python3.11/site-packages/hugchat/login.py", line 134, in _sign_in_with_email
    raise Exception("wrong username or password")
Exception: wrong username or password

During handling of the above exception, another exception occurred:

Traceback (most recent call last):
  File "/home/wendellast/Documents/GitHub/Gui/gui.py", line 39, in action_response
    gui_resp = response_gui(self.input.value) + 1
               ^^^^^^^^^^^^^^^^^^^^^^^^^^^^^^
  File "/home/wendellast/Documents/GitHub/Gui/api/orange.py", line 58, in response_gui
    return llm(resp)
           ^^^^^^^^^
  File "/home/wendellast/Documents/GitHub/Gui/venv/lib/python3.11/site-packages/langchain_core/_api/deprecation.py", line 145, in warning_emitting_wrapper
    return wrapped(*args, **kwargs)
           ^^^^^^^^^^^^^^^^^^^^^^^^
  File "/home/wendellast/Documents/GitHub/Gui/venv/lib/python3.11/site-packages/langchain_core/language_models/llms.py", line 991, in __call__
    self.generate(
  File "/home/wendellast/Documents/GitHub/Gui/venv/lib/python3.11/site-packages/langchain_core/language_models/llms.py", line 741, in generate
    output = self._generate_helper(
             ^^^^^^^^^^^^^^^^^^^^^^
  File "/home/wendellast/Documents/GitHub/Gui/venv/lib/python3.11/site-packages/langchain_core/language_models/llms.py", line 605, in _generate_helper
    raise e
  File "/home/wendellast/Documents/GitHub/Gui/venv/lib/python3.11/site-packages/langchain_core/language_models/llms.py", line 592, in _generate_helper
    self._generate(
  File "/home/wendellast/Documents/GitHub/Gui/venv/lib/python3.11/site-packages/langchain_core/language_models/llms.py", line 1177, in _generate
    self._call(prompt, stop=stop, run_manager=run_manager, **kwargs)
  File "/home/wendellast/Documents/GitHub/Gui/api/apple.py", line 101, in _call
    self.create_chatbot() if not self.chatbot else None
    ^^^^^^^^^^^^^^^^^^^^^
  File "/home/wendellast/Documents/GitHub/Gui/api/apple.py", line 75, in create_chatbot
    raise ValueError(
ValueError: LogIn failed. Please check your credentials or cookie_path. wrong username or password
ERROR:root:Erro na sua_funcao: Response Error 
Traceback (most recent call last):
  File "/home/wendellast/Documents/GitHub/Gui/api/apple.py", line 56, in create_chatbot
    cookies = sign.login()
              ^^^^^^^^^^^^
  File "/home/wendellast/Documents/GitHub/Gui/venv/lib/python3.11/site-packages/hugchat/login.py", line 33, in login
    self._sign_in_with_email()
  File "/home/wendellast/Documents/GitHub/Gui/venv/lib/python3.11/site-packages/hugchat/login.py", line 134, in _sign_in_with_email
    raise Exception("wrong username or password")
Exception: wrong username or password

During handling of the above exception, another exception occurred:

Traceback (most recent call last):
  File "/home/wendellast/Documents/GitHub/Gui/gui.py", line 39, in action_response
    gui_resp = response_gui(self.input.value)
               ^^^^^^^^^^^^^^^^^^^^^^^^^^^^^^
  File "/home/wendellast/Documents/GitHub/Gui/api/orange.py", line 58, in response_gui
    return llm(resp)
           ^^^^^^^^^
  File "/home/wendellast/Documents/GitHub/Gui/venv/lib/python3.11/site-packages/langchain_core/_api/deprecation.py", line 145, in warning_emitting_wrapper
    return wrapped(*args, **kwargs)
           ^^^^^^^^^^^^^^^^^^^^^^^^
  File "/home/wendellast/Documents/GitHub/Gui/venv/lib/python3.11/site-packages/langchain_core/language_models/llms.py", line 991, in __call__
    self.generate(
  File "/home/wendellast/Documents/GitHub/Gui/venv/lib/python3.11/site-packages/langchain_core/language_models/llms.py", line 741, in generate
    output = self._generate_helper(
             ^^^^^^^^^^^^^^^^^^^^^^
  File "/home/wendellast/Documents/GitHub/Gui/venv/lib/python3.11/site-packages/langchain_core/language_models/llms.py", line 605, in _generate_helper
    raise e
  File "/home/wendellast/Documents/GitHub/Gui/venv/lib/python3.11/site-packages/langchain_core/language_models/llms.py", line 592, in _generate_helper
    self._generate(
  File "/home/wendellast/Documents/GitHub/Gui/venv/lib/python3.11/site-packages/langchain_core/language_models/llms.py", line 1177, in _generate
    self._call(prompt, stop=stop, run_manager=run_manager, **kwargs)
  File "/home/wendellast/Documents/GitHub/Gui/api/apple.py", line 101, in _call
    self.create_chatbot() if not self.chatbot else None
    ^^^^^^^^^^^^^^^^^^^^^
  File "/home/wendellast/Documents/GitHub/Gui/api/apple.py", line 75, in create_chatbot
    raise ValueError(
ValueError: LogIn failed. Please check your credentials or cookie_path. wrong username or password
ERROR:root:Erro na sua_funcao: Response Error 
Traceback (most recent call last):
  File "/home/wendellast/Documents/GitHub/Gui/api/apple.py", line 56, in create_chatbot
    cookies = sign.login()
              ^^^^^^^^^^^^
  File "/home/wendellast/Documents/GitHub/Gui/venv/lib/python3.11/site-packages/hugchat/login.py", line 33, in login
    self._sign_in_with_email()
  File "/home/wendellast/Documents/GitHub/Gui/venv/lib/python3.11/site-packages/hugchat/login.py", line 134, in _sign_in_with_email
    raise Exception("wrong username or password")
Exception: wrong username or password

During handling of the above exception, another exception occurred:

Traceback (most recent call last):
  File "/home/wendellast/Documents/GitHub/Gui/gui.py", line 39, in action_response
    gui_resp = response_gui(self.input.value)
               ^^^^^^^^^^^^^^^^^^^^^^^^^^^^^^
  File "/home/wendellast/Documents/GitHub/Gui/api/orange.py", line 58, in response_gui
    return llm(resp)
           ^^^^^^^^^
  File "/home/wendellast/Documents/GitHub/Gui/venv/lib/python3.11/site-packages/langchain_core/_api/deprecation.py", line 145, in warning_emitting_wrapper
    return wrapped(*args, **kwargs)
           ^^^^^^^^^^^^^^^^^^^^^^^^
  File "/home/wendellast/Documents/GitHub/Gui/venv/lib/python3.11/site-packages/langchain_core/language_models/llms.py", line 991, in __call__
    self.generate(
  File "/home/wendellast/Documents/GitHub/Gui/venv/lib/python3.11/site-packages/langchain_core/language_models/llms.py", line 741, in generate
    output = self._generate_helper(
             ^^^^^^^^^^^^^^^^^^^^^^
  File "/home/wendellast/Documents/GitHub/Gui/venv/lib/python3.11/site-packages/langchain_core/language_models/llms.py", line 605, in _generate_helper
    raise e
  File "/home/wendellast/Documents/GitHub/Gui/venv/lib/python3.11/site-packages/langchain_core/language_models/llms.py", line 592, in _generate_helper
    self._generate(
  File "/home/wendellast/Documents/GitHub/Gui/venv/lib/python3.11/site-packages/langchain_core/language_models/llms.py", line 1177, in _generate
    self._call(prompt, stop=stop, run_manager=run_manager, **kwargs)
  File "/home/wendellast/Documents/GitHub/Gui/api/apple.py", line 101, in _call
    self.create_chatbot() if not self.chatbot else None
    ^^^^^^^^^^^^^^^^^^^^^
  File "/home/wendellast/Documents/GitHub/Gui/api/apple.py", line 75, in create_chatbot
    raise ValueError(
ValueError: LogIn failed. Please check your credentials or cookie_path. wrong username or password
ERROR:root:Erro na sua_funcao: Response Error 
Traceback (most recent call last):
  File "/home/wendellast/Documents/GitHub/Gui/api/apple.py", line 56, in create_chatbot
    cookies = sign.login()
              ^^^^^^^^^^^^
  File "/home/wendellast/Documents/GitHub/Gui/venv/lib/python3.11/site-packages/hugchat/login.py", line 33, in login
    self._sign_in_with_email()
  File "/home/wendellast/Documents/GitHub/Gui/venv/lib/python3.11/site-packages/hugchat/login.py", line 134, in _sign_in_with_email
    raise Exception("wrong username or password")
Exception: wrong username or password

During handling of the above exception, another exception occurred:

Traceback (most recent call last):
  File "/home/wendellast/Documents/GitHub/Gui/gui.py", line 39, in action_response
    gui_resp = response_gui(self.input.value)
               ^^^^^^^^^^^^^^^^^^^^^^^^^^^^^^
  File "/home/wendellast/Documents/GitHub/Gui/api/orange.py", line 58, in response_gui
    return llm(resp)
           ^^^^^^^^^
  File "/home/wendellast/Documents/GitHub/Gui/venv/lib/python3.11/site-packages/langchain_core/_api/deprecation.py", line 145, in warning_emitting_wrapper
    return wrapped(*args, **kwargs)
           ^^^^^^^^^^^^^^^^^^^^^^^^
  File "/home/wendellast/Documents/GitHub/Gui/venv/lib/python3.11/site-packages/langchain_core/language_models/llms.py", line 991, in __call__
    self.generate(
  File "/home/wendellast/Documents/GitHub/Gui/venv/lib/python3.11/site-packages/langchain_core/language_models/llms.py", line 741, in generate
    output = self._generate_helper(
             ^^^^^^^^^^^^^^^^^^^^^^
  File "/home/wendellast/Documents/GitHub/Gui/venv/lib/python3.11/site-packages/langchain_core/language_models/llms.py", line 605, in _generate_helper
    raise e
  File "/home/wendellast/Documents/GitHub/Gui/venv/lib/python3.11/site-packages/langchain_core/language_models/llms.py", line 592, in _generate_helper
    self._generate(
  File "/home/wendellast/Documents/GitHub/Gui/venv/lib/python3.11/site-packages/langchain_core/language_models/llms.py", line 1177, in _generate
    self._call(prompt, stop=stop, run_manager=run_manager, **kwargs)
  File "/home/wendellast/Documents/GitHub/Gui/api/apple.py", line 101, in _call
    self.create_chatbot() if not self.chatbot else None
    ^^^^^^^^^^^^^^^^^^^^^
  File "/home/wendellast/Documents/GitHub/Gui/api/apple.py", line 75, in create_chatbot
    raise ValueError(
ValueError: LogIn failed. Please check your credentials or cookie_path. wrong username or password
ERROR:root:Erro na sua_funcao: Response Error 
Traceback (most recent call last):
  File "/home/wendellast/Documents/GitHub/Gui/api/apple.py", line 56, in create_chatbot
    cookies = sign.login()
              ^^^^^^^^^^^^
  File "/home/wendellast/Documents/GitHub/Gui/venv/lib/python3.11/site-packages/hugchat/login.py", line 33, in login
    self._sign_in_with_email()
  File "/home/wendellast/Documents/GitHub/Gui/venv/lib/python3.11/site-packages/hugchat/login.py", line 134, in _sign_in_with_email
    raise Exception("wrong username or password")
Exception: wrong username or password

During handling of the above exception, another exception occurred:

Traceback (most recent call last):
  File "/home/wendellast/Documents/GitHub/Gui/gui.py", line 39, in action_response
    gui_resp = response_gui(self.input.value)
               ^^^^^^^^^^^^^^^^^^^^^^^^^^^^^^
  File "/home/wendellast/Documents/GitHub/Gui/api/orange.py", line 58, in response_gui
    return llm(resp)
           ^^^^^^^^^
  File "/home/wendellast/Documents/GitHub/Gui/venv/lib/python3.11/site-packages/langchain_core/_api/deprecation.py", line 145, in warning_emitting_wrapper
    return wrapped(*args, **kwargs)
           ^^^^^^^^^^^^^^^^^^^^^^^^
  File "/home/wendellast/Documents/GitHub/Gui/venv/lib/python3.11/site-packages/langchain_core/language_models/llms.py", line 991, in __call__
    self.generate(
  File "/home/wendellast/Documents/GitHub/Gui/venv/lib/python3.11/site-packages/langchain_core/language_models/llms.py", line 741, in generate
    output = self._generate_helper(
             ^^^^^^^^^^^^^^^^^^^^^^
  File "/home/wendellast/Documents/GitHub/Gui/venv/lib/python3.11/site-packages/langchain_core/language_models/llms.py", line 605, in _generate_helper
    raise e
  File "/home/wendellast/Documents/GitHub/Gui/venv/lib/python3.11/site-packages/langchain_core/language_models/llms.py", line 592, in _generate_helper
    self._generate(
  File "/home/wendellast/Documents/GitHub/Gui/venv/lib/python3.11/site-packages/langchain_core/language_models/llms.py", line 1177, in _generate
    self._call(prompt, stop=stop, run_manager=run_manager, **kwargs)
  File "/home/wendellast/Documents/GitHub/Gui/api/apple.py", line 101, in _call
    self.create_chatbot() if not self.chatbot else None
    ^^^^^^^^^^^^^^^^^^^^^
  File "/home/wendellast/Documents/GitHub/Gui/api/apple.py", line 75, in create_chatbot
    raise ValueError(
ValueError: LogIn failed. Please check your credentials or cookie_path. wrong username or password
ERROR:root:Erro na sua_funcao: Response Error 
Traceback (most recent call last):
  File "/home/wendellast/Documents/GitHub/Gui/api/apple.py", line 56, in create_chatbot
    cookies = sign.login()
              ^^^^^^^^^^^^
  File "/home/wendellast/Documents/GitHub/Gui/venv/lib/python3.11/site-packages/hugchat/login.py", line 33, in login
    self._sign_in_with_email()
  File "/home/wendellast/Documents/GitHub/Gui/venv/lib/python3.11/site-packages/hugchat/login.py", line 134, in _sign_in_with_email
    raise Exception("wrong username or password")
Exception: wrong username or password

During handling of the above exception, another exception occurred:

Traceback (most recent call last):
  File "/home/wendellast/Documents/GitHub/Gui/gui.py", line 39, in action_response
    gui_resp = response_gui(self.input.value)
               ^^^^^^^^^^^^^^^^^^^^^^^^^^^^^^
  File "/home/wendellast/Documents/GitHub/Gui/api/orange.py", line 58, in response_gui
    return llm(resp)
           ^^^^^^^^^
  File "/home/wendellast/Documents/GitHub/Gui/venv/lib/python3.11/site-packages/langchain_core/_api/deprecation.py", line 145, in warning_emitting_wrapper
    return wrapped(*args, **kwargs)
           ^^^^^^^^^^^^^^^^^^^^^^^^
  File "/home/wendellast/Documents/GitHub/Gui/venv/lib/python3.11/site-packages/langchain_core/language_models/llms.py", line 991, in __call__
    self.generate(
  File "/home/wendellast/Documents/GitHub/Gui/venv/lib/python3.11/site-packages/langchain_core/language_models/llms.py", line 741, in generate
    output = self._generate_helper(
             ^^^^^^^^^^^^^^^^^^^^^^
  File "/home/wendellast/Documents/GitHub/Gui/venv/lib/python3.11/site-packages/langchain_core/language_models/llms.py", line 605, in _generate_helper
    raise e
  File "/home/wendellast/Documents/GitHub/Gui/venv/lib/python3.11/site-packages/langchain_core/language_models/llms.py", line 592, in _generate_helper
    self._generate(
  File "/home/wendellast/Documents/GitHub/Gui/venv/lib/python3.11/site-packages/langchain_core/language_models/llms.py", line 1177, in _generate
    self._call(prompt, stop=stop, run_manager=run_manager, **kwargs)
  File "/home/wendellast/Documents/GitHub/Gui/api/apple.py", line 101, in _call
    self.create_chatbot() if not self.chatbot else None
    ^^^^^^^^^^^^^^^^^^^^^
  File "/home/wendellast/Documents/GitHub/Gui/api/apple.py", line 75, in create_chatbot
    raise ValueError(
ValueError: LogIn failed. Please check your credentials or cookie_path. wrong username or password
ERROR:root:Erro na sua_funcao: Response Error 
Traceback (most recent call last):
  File "/home/wendellast/Documents/GitHub/Gui/api/apple.py", line 56, in create_chatbot
    cookies = sign.login()
              ^^^^^^^^^^^^
  File "/home/wendellast/Documents/GitHub/Gui/venv/lib/python3.11/site-packages/hugchat/login.py", line 33, in login
    self._sign_in_with_email()
  File "/home/wendellast/Documents/GitHub/Gui/venv/lib/python3.11/site-packages/hugchat/login.py", line 134, in _sign_in_with_email
    raise Exception("wrong username or password")
Exception: wrong username or password

During handling of the above exception, another exception occurred:

Traceback (most recent call last):
  File "/home/wendellast/Documents/GitHub/Gui/gui.py", line 39, in action_response
    gui_resp = response_gui(self.input.value)
               ^^^^^^^^^^^^^^^^^^^^^^^^^^^^^^
  File "/home/wendellast/Documents/GitHub/Gui/api/orange.py", line 58, in response_gui
    return llm(resp)
           ^^^^^^^^^
  File "/home/wendellast/Documents/GitHub/Gui/venv/lib/python3.11/site-packages/langchain_core/_api/deprecation.py", line 145, in warning_emitting_wrapper
    return wrapped(*args, **kwargs)
           ^^^^^^^^^^^^^^^^^^^^^^^^
  File "/home/wendellast/Documents/GitHub/Gui/venv/lib/python3.11/site-packages/langchain_core/language_models/llms.py", line 991, in __call__
    self.generate(
  File "/home/wendellast/Documents/GitHub/Gui/venv/lib/python3.11/site-packages/langchain_core/language_models/llms.py", line 741, in generate
    output = self._generate_helper(
             ^^^^^^^^^^^^^^^^^^^^^^
  File "/home/wendellast/Documents/GitHub/Gui/venv/lib/python3.11/site-packages/langchain_core/language_models/llms.py", line 605, in _generate_helper
    raise e
  File "/home/wendellast/Documents/GitHub/Gui/venv/lib/python3.11/site-packages/langchain_core/language_models/llms.py", line 592, in _generate_helper
    self._generate(
  File "/home/wendellast/Documents/GitHub/Gui/venv/lib/python3.11/site-packages/langchain_core/language_models/llms.py", line 1177, in _generate
    self._call(prompt, stop=stop, run_manager=run_manager, **kwargs)
  File "/home/wendellast/Documents/GitHub/Gui/api/apple.py", line 101, in _call
    self.create_chatbot() if not self.chatbot else None
    ^^^^^^^^^^^^^^^^^^^^^
  File "/home/wendellast/Documents/GitHub/Gui/api/apple.py", line 75, in create_chatbot
    raise ValueError(
ValueError: LogIn failed. Please check your credentials or cookie_path. wrong username or password
ERROR:root:Erro na sua_funcao: Response Error 
Traceback (most recent call last):
  File "/home/wendellast/Documents/GitHub/Gui/api/apple.py", line 56, in create_chatbot
    cookies = sign.login()
              ^^^^^^^^^^^^
  File "/home/wendellast/Documents/GitHub/Gui/venv/lib/python3.11/site-packages/hugchat/login.py", line 33, in login
    self._sign_in_with_email()
  File "/home/wendellast/Documents/GitHub/Gui/venv/lib/python3.11/site-packages/hugchat/login.py", line 134, in _sign_in_with_email
    raise Exception("wrong username or password")
Exception: wrong username or password

During handling of the above exception, another exception occurred:

Traceback (most recent call last):
  File "/home/wendellast/Documents/GitHub/Gui/gui.py", line 39, in action_response
    gui_resp = response_gui(self.input.value)
               ^^^^^^^^^^^^^^^^^^^^^^^^^^^^^^
  File "/home/wendellast/Documents/GitHub/Gui/api/orange.py", line 58, in response_gui
    return llm(resp)
           ^^^^^^^^^
  File "/home/wendellast/Documents/GitHub/Gui/venv/lib/python3.11/site-packages/langchain_core/_api/deprecation.py", line 145, in warning_emitting_wrapper
    return wrapped(*args, **kwargs)
           ^^^^^^^^^^^^^^^^^^^^^^^^
  File "/home/wendellast/Documents/GitHub/Gui/venv/lib/python3.11/site-packages/langchain_core/language_models/llms.py", line 991, in __call__
    self.generate(
  File "/home/wendellast/Documents/GitHub/Gui/venv/lib/python3.11/site-packages/langchain_core/language_models/llms.py", line 741, in generate
    output = self._generate_helper(
             ^^^^^^^^^^^^^^^^^^^^^^
  File "/home/wendellast/Documents/GitHub/Gui/venv/lib/python3.11/site-packages/langchain_core/language_models/llms.py", line 605, in _generate_helper
    raise e
  File "/home/wendellast/Documents/GitHub/Gui/venv/lib/python3.11/site-packages/langchain_core/language_models/llms.py", line 592, in _generate_helper
    self._generate(
  File "/home/wendellast/Documents/GitHub/Gui/venv/lib/python3.11/site-packages/langchain_core/language_models/llms.py", line 1177, in _generate
    self._call(prompt, stop=stop, run_manager=run_manager, **kwargs)
  File "/home/wendellast/Documents/GitHub/Gui/api/apple.py", line 101, in _call
    self.create_chatbot() if not self.chatbot else None
    ^^^^^^^^^^^^^^^^^^^^^
  File "/home/wendellast/Documents/GitHub/Gui/api/apple.py", line 75, in create_chatbot
    raise ValueError(
ValueError: LogIn failed. Please check your credentials or cookie_path. wrong username or password
ERROR:root:Erro na sua_funcao: Response Error 
Traceback (most recent call last):
  File "/home/wendellast/Documents/GitHub/Gui/gui.py", line 39, in action_response
    gui_resp = response_gui(self.input.value) +1
               ~~~~~~~~~~~~~~~~~~~~~~~~~~~~~~~^~
TypeError: can only concatenate str (not "int") to str
ERROR:root:Erro na sua_funcao: Response Error 
Traceback (most recent call last):
  File "/home/wendellast/Documents/GitHub/Gui/gui.py", line 39, in action_response
    gui_resp = response_gui(self.input.value) +1
               ~~~~~~~~~~~~~~~~~~~~~~~~~~~~~~~^~
TypeError: can only concatenate str (not "int") to str
